[0m11:06:44.428226 [debug] [MainThread]: Sending event: {'category': 'dbt', 'action': 'invocation', 'label': 'start', 'context': [<snowplow_tracker.self_describing_json.SelfDescribingJson object at 0x10aaae530>, <snowplow_tracker.self_describing_json.SelfDescribingJson object at 0x10bc17160>, <snowplow_tracker.self_describing_json.SelfDescribingJson object at 0x10bc16a40>]}


============================== 11:06:44.437160 | c47326e3-0c06-471c-9158-cee6437bb1c8 ==============================
[0m11:06:44.437160 [info ] [MainThread]: Running with dbt=1.5.1
[0m11:06:44.438466 [debug] [MainThread]: running dbt with arguments {'printer_width': '80', 'indirect_selection': 'eager', 'write_json': 'True', 'log_cache_events': 'False', 'partial_parse': 'True', 'cache_selected_only': 'False', 'profiles_dir': '/Users/javiertoloza/.dbt', 'fail_fast': 'False', 'debug': 'False', 'log_path': 'logs', 'warn_error': 'None', 'version_check': 'True', 'use_colors': 'True', 'use_experimental_parser': 'False', 'no_print': 'None', 'quiet': 'False', 'warn_error_options': 'WarnErrorOptions(include=[], exclude=[])', 'static_parser': 'True', 'introspect': 'True', 'log_format': 'default', 'target_path': 'None', 'send_anonymous_usage_stats': 'True'}
[0m11:06:44.440231 [info ] [MainThread]: dbt version: 1.5.1
[0m11:06:44.441163 [info ] [MainThread]: python version: 3.10.5
[0m11:06:44.441974 [info ] [MainThread]: python path: /Library/Frameworks/Python.framework/Versions/3.10/bin/python3
[0m11:06:44.442756 [info ] [MainThread]: os info: macOS-14.2.1-x86_64-i386-64bit
[0m11:06:44.443803 [info ] [MainThread]: Using profiles.yml file at /Users/javiertoloza/.dbt/profiles.yml
[0m11:06:44.444626 [info ] [MainThread]: Using dbt_project.yml file at /Users/javiertoloza/Documents/Documents - Javierâ€™s MacBook Pro/GitHub/dbt_project.yml
[0m11:06:44.445596 [info ] [MainThread]: Configuration:
[0m11:06:46.383844 [debug] [MainThread]: Traceback (most recent call last):
  File "/Library/Frameworks/Python.framework/Versions/3.10/lib/python3.10/site-packages/dbt/adapters/factory.py", line 57, in load_plugin
    mod: Any = import_module("." + name, "dbt.adapters")
  File "/Library/Frameworks/Python.framework/Versions/3.10/lib/python3.10/importlib/__init__.py", line 126, in import_module
    return _bootstrap._gcd_import(name[level:], package, level)
  File "<frozen importlib._bootstrap>", line 1050, in _gcd_import
  File "<frozen importlib._bootstrap>", line 1027, in _find_and_load
  File "<frozen importlib._bootstrap>", line 1006, in _find_and_load_unlocked
  File "<frozen importlib._bootstrap>", line 688, in _load_unlocked
  File "<frozen importlib._bootstrap_external>", line 883, in exec_module
  File "<frozen importlib._bootstrap>", line 241, in _call_with_frames_removed
  File "/Library/Frameworks/Python.framework/Versions/3.10/lib/python3.10/site-packages/dbt/adapters/snowflake/__init__.py", line 4, in <module>
    from dbt.adapters.snowflake.relation import SnowflakeRelation  # noqa
  File "/Library/Frameworks/Python.framework/Versions/3.10/lib/python3.10/site-packages/dbt/adapters/snowflake/relation.py", line 5, in <module>
    from dbt.adapters.relation_configs import RelationConfigChangeAction, RelationResults
ModuleNotFoundError: No module named 'dbt.adapters.relation_configs'

[0m11:06:46.384746 [error] [MainThread]: Encountered an error:
No module named 'dbt.adapters.relation_configs'
[0m11:06:46.391191 [error] [MainThread]: Traceback (most recent call last):
  File "/Library/Frameworks/Python.framework/Versions/3.10/lib/python3.10/site-packages/dbt/cli/requires.py", line 86, in wrapper
    result, success = func(*args, **kwargs)
  File "/Library/Frameworks/Python.framework/Versions/3.10/lib/python3.10/site-packages/dbt/cli/requires.py", line 71, in wrapper
    return func(*args, **kwargs)
  File "/Library/Frameworks/Python.framework/Versions/3.10/lib/python3.10/site-packages/dbt/cli/main.py", line 415, in debug
    results = task.run()
  File "/Library/Frameworks/Python.framework/Versions/3.10/lib/python3.10/site-packages/dbt/task/debug.py", line 110, in run
    self.test_configuration()
  File "/Library/Frameworks/Python.framework/Versions/3.10/lib/python3.10/site-packages/dbt/task/debug.py", line 294, in test_configuration
    profile_status = self._load_profile()
  File "/Library/Frameworks/Python.framework/Versions/3.10/lib/python3.10/site-packages/dbt/task/debug.py", line 254, in _load_profile
    profile: Profile = Profile.render(
  File "/Library/Frameworks/Python.framework/Versions/3.10/lib/python3.10/site-packages/dbt/config/profile.py", line 436, in render
    return cls.from_raw_profiles(
  File "/Library/Frameworks/Python.framework/Versions/3.10/lib/python3.10/site-packages/dbt/config/profile.py", line 401, in from_raw_profiles
    return cls.from_raw_profile_info(
  File "/Library/Frameworks/Python.framework/Versions/3.10/lib/python3.10/site-packages/dbt/config/profile.py", line 355, in from_raw_profile_info
    credentials: Credentials = cls._credentials_from_profile(
  File "/Library/Frameworks/Python.framework/Versions/3.10/lib/python3.10/site-packages/dbt/config/profile.py", line 165, in _credentials_from_profile
    cls = load_plugin(typename)
  File "/Library/Frameworks/Python.framework/Versions/3.10/lib/python3.10/site-packages/dbt/adapters/factory.py", line 202, in load_plugin
    return FACTORY.load_plugin(name)
  File "/Library/Frameworks/Python.framework/Versions/3.10/lib/python3.10/site-packages/dbt/adapters/factory.py", line 57, in load_plugin
    mod: Any = import_module("." + name, "dbt.adapters")
  File "/Library/Frameworks/Python.framework/Versions/3.10/lib/python3.10/importlib/__init__.py", line 126, in import_module
    return _bootstrap._gcd_import(name[level:], package, level)
  File "<frozen importlib._bootstrap>", line 1050, in _gcd_import
  File "<frozen importlib._bootstrap>", line 1027, in _find_and_load
  File "<frozen importlib._bootstrap>", line 1006, in _find_and_load_unlocked
  File "<frozen importlib._bootstrap>", line 688, in _load_unlocked
  File "<frozen importlib._bootstrap_external>", line 883, in exec_module
  File "<frozen importlib._bootstrap>", line 241, in _call_with_frames_removed
  File "/Library/Frameworks/Python.framework/Versions/3.10/lib/python3.10/site-packages/dbt/adapters/snowflake/__init__.py", line 4, in <module>
    from dbt.adapters.snowflake.relation import SnowflakeRelation  # noqa
  File "/Library/Frameworks/Python.framework/Versions/3.10/lib/python3.10/site-packages/dbt/adapters/snowflake/relation.py", line 5, in <module>
    from dbt.adapters.relation_configs import RelationConfigChangeAction, RelationResults
ModuleNotFoundError: No module named 'dbt.adapters.relation_configs'

[0m11:06:46.393919 [debug] [MainThread]: Command `dbt debug` failed at 11:06:46.393251 after 2.02 seconds
[0m11:06:46.394596 [debug] [MainThread]: Sending event: {'category': 'dbt', 'action': 'invocation', 'label': 'end', 'context': [<snowplow_tracker.self_describing_json.SelfDescribingJson object at 0x10aaae530>, <snowplow_tracker.self_describing_json.SelfDescribingJson object at 0x10b0594e0>, <snowplow_tracker.self_describing_json.SelfDescribingJson object at 0x10b47e7a0>]}
[0m11:06:46.395308 [debug] [MainThread]: Flushing usage events
